Workbook

Sheet Tổng quan
A1: BÁO CÁO KIỂM THỬ — MÀN HÌNH CÁ NHÂN NHÂN VIÊN EM-01 → EM-18
A2: DigiTalent AI · Phần việc BE1 + FE1 · API /api/v1/me/* và 18 trang /enterprise/me/*
A4: Thông tin kiểm thử
A5: Người thực hiện | B5: Nguyễn Thiện Hoàng
A6: Ngày thực hiện | B6: 09/10/2026
A7: Nhánh / commit | B7: feature/DT-em01-em18-tests @ 3d26e15
A8: Frontend | B8: http://localhost:5173 — React 19 + Vite (npm run dev)
A9: Backend | B9: http://localhost:5000 — ASP.NET Core 8, môi trường Development
A10: Cơ sở dữ liệu | B10: PostgreSQL 16 (Docker, DB demo local) — dữ liệu demo do DbSeeder tạo lại trước khi chạy
A11: Trình duyệt | B11: Chromium (Playwright 1.58), cửa sổ 1440×900, tiếng Việt
A12: Tài khoản test | B12: employee@digitalent.ai (Nhân viên Kế toán) · manager@digitalent.ai (Quản lý) — mật khẩu Admin@1234
A13: Cách chạy | B13: Test thủ công được thực hiện tự động bằng trình duyệt theo đúng các bước trong sheet "Chi tiết bước & Evidence"; mỗi bước chụp 1 ảnh
A15: Kết quả test thủ công (tính bằng công thức)
A16: Tổng số test case | B16: =COUNTA('Test cases'!$B$5:$B$24)
A17: Test case Pass | B17: =COUNTIF('Test cases'!$K$5:$K$24,"Pass")
A18: Test case Fail | B18: =COUNTIF('Test cases'!$K$5:$K$24,"Fail")
A19: Tổng số bước | B19: =COUNTA('Chi tiết bước & Evidence'!$A$5:$A$63)
A20: Bước Pass | B20: =COUNTIF('Chi tiết bước & Evidence'!$G$5:$G$63,"Pass")
A21: Bước Fail | B21: =COUNTIF('Chi tiết bước & Evidence'!$G$5:$G$63,"Fail")
A22: Tỉ lệ test case đạt | B22: =IF(B16=0,0,B17/B16)
A24: Kết quả test tự động (từ sheet "Test tự động")
A25: Tổng số test tự động cho EM | B25: ='Test tự động'!F22
A26: Đạt | B26: ='Test tự động'!G22
A27: Không đạt | B27: ='Test tự động'!H22
A29: Cách đọc ảnh evidence
A30: Khung đỏ | B30: Phần tử được thao tác (nút, ô nhập) hoặc được kiểm tra ở bước đó
A31: Nhãn vàng (góc phải dưới) | B31: Mã test case và nội dung bước, ví dụ "TC-EM16-01 · Bước 3: Chọn tệp sai định dạng virus.exe"
A32: Bước "Bấm …" | B32: Ảnh chụp ngay TRƯỚC khi bấm để thấy rõ nút; kết quả của cú bấm nằm ở cột "Kết quả thực tế" và ảnh bước kế tiếp
A33: Ảnh gốc | B33: Ảnh nhúng được thu nhỏ còn 720×450; ảnh gốc 1440×900 tạo lại bằng docs/testing/scripts/em_evidence.py (xem README cùng thư mục)

Sheet Test cases
A1: DANH SÁCH TEST CASE — MÀN HÌNH CÁ NHÂN NHÂN VIÊN (EM-01 → EM-18)
A2: Trạng thái và số bước được tính bằng công thức từ sheet "Chi tiết bước & Evidence". Ngày test: 09/10/2026 · Người test: Nguyễn Thiện Hoàng
A4: STT | B4: Mã TC | C4: Màn hình | D4: Tên test case | E4: Mục tiêu | F4: Tiền điều kiện | G4: Dữ liệu test | H4: Số bước | I4: Số bước Fail | J4: Kết quả mong đợi | K4: Trạng thái | L4: Ngày test | M4: Người test
A5: 1 | B5: TC-EM01-01 | C5: EM-01 Bảng phát triển của tôi | D5: Đăng nhập và xem bảng phát triển cá nhân | E5: Nhân viên thấy tổng quan năng lực, khóa học, nhiệm vụ và chứng chỉ của chính mình. | F5: Tài khoản employee@digitalent.ai đã có dữ liệu demo (3 khóa, 3 nhiệm vụ, 1 chứng chỉ). | G5: employee@digitalent.ai / Admin@1234 | H5: =COUNTIF('Chi tiết bước & Evidence'!$A$5:$A$63,B5) | I5: =COUNTIFS('Chi tiết bước & Evidence'!$A$5:$A$63,B5,'Chi tiết bước & Evidence'!$G$5:$G$63,"<>Pass") | J5: Vào /enterprise/me, hiển thị 4 chỉ số và khóa đang học A4-I. | K5: =IF(H5=0,"Blocked",IF(I5=0,"Pass","Fail")) | L5: 09/10/2026 | M5: Nguyễn Thiện Hoàng
A6: 2 | B6: TC-EM02-01 | C6: EM-02 Hồ sơ năng lực của tôi | D6: Xem hồ sơ năng lực theo chuẩn vị trí | E6: Nhân viên thấy mức năng lực đã xác nhận so với mức yêu cầu của vị trí Kế toán. | F6: Đã đăng nhập bằng employee@. | G6: — | H6: =COUNTIF('Chi tiết bước & Evidence'!$A$5:$A$63,B6) | I6: =COUNTIFS('Chi tiết bước & Evidence'!$A$5:$A$63,B6,'Chi tiết bước & Evidence'!$G$5:$G$63,"<>Pass") | J6: Danh sách năng lực có mức hiện tại và mức yêu cầu. | K6: =IF(H6=0,"Blocked",IF(I6=0,"Pass","Fail")) | L6: 09/10/2026 | M6: Nguyễn Thiện Hoàng
A7: 3 | B7: TC-EM03-01 | C7: EM-03 Khoảng trống năng lực | D7: Xem khoảng trống năng lực và mở khóa học được gợi ý | E7: Nhân viên biết năng lực nào còn thiếu và khóa học nào giúp bù khoảng trống. | F7: Đã đăng nhập bằng employee@ (vị trí Kế toán). | G7: — | H7: =COUNTIF('Chi tiết bước & Evidence'!$A$5:$A$63,B7) | I7: =COUNTIFS('Chi tiết bước & Evidence'!$A$5:$A$63,B7,'Chi tiết bước & Evidence'!$G$5:$G$63,"<>Pass") | J7: Các năng lực thiếu có mức độ và gợi ý khóa học; bấm gợi ý mở đúng khóa. | K7: =IF(H7=0,"Blocked",IF(I7=0,"Pass","Fail")) | L7: 09/10/2026 | M7: Nguyễn Thiện Hoàng
A8: 4 | B8: TC-EM04-01 | C8: EM-04 Dòng thời gian minh chứng | D8: Lọc dòng thời gian minh chứng theo trạng thái | E8: Nhân viên xem lại các bài nộp, phản hồi và lọc theo trạng thái duyệt. | F8: Đã đăng nhập bằng employee@; có 1 bài cần chỉnh sửa và 1 bài đã duyệt. | G8: Tab "Cần chỉnh sửa" | H8: =COUNTIF('Chi tiết bước & Evidence'!$A$5:$A$63,B8) | I8: =COUNTIFS('Chi tiết bước & Evidence'!$A$5:$A$63,B8,'Chi tiết bước & Evidence'!$G$5:$G$63,"<>Pass") | J8: Chỉ còn minh chứng cần chỉnh sửa. | K8: =IF(H8=0,"Blocked",IF(I8=0,"Pass","Fail")) | L8: 09/10/2026 | M8: Nguyễn Thiện Hoàng
A9: 5 | B9: TC-EM05-01 | C9: EM-05 Lộ trình học tập | D9: Ghi danh khóa học được đề xuất trong lộ trình | E9: Nhân viên tự ghi danh khóa học được gợi ý để bù khoảng trống năng lực. | F9: Đã đăng nhập bằng employee@; lộ trình có khóa được đề xuất chưa ghi danh. | G9: Khóa đề xuất đầu tiên | H9: =COUNTIF('Chi tiết bước & Evidence'!$A$5:$A$63,B9) | I9: =COUNTIFS('Chi tiết bước & Evidence'!$A$5:$A$63,B9,'Chi tiết bước & Evidence'!$G$5:$G$63,"<>Pass") | J9: Ghi danh thành công và mở trang chi tiết khóa học. | K9: =IF(H9=0,"Blocked",IF(I9=0,"Pass","Fail")) | L9: 09/10/2026 | M9: Nguyễn Thiện Hoàng
A10: 6 | B10: TC-EM06-01 | C10: EM-06 Khóa học của tôi | D10: Tìm kiếm và lọc khóa học của tôi | E10: Nhân viên tìm nhanh khóa học theo mã/tên và lọc theo trạng thái. | F10: Đã đăng nhập bằng employee@. | G10: Từ khóa "A1"; tab "Đã xong" | H10: =COUNTIF('Chi tiết bước & Evidence'!$A$5:$A$63,B10) | I10: =COUNTIFS('Chi tiết bước & Evidence'!$A$5:$A$63,B10,'Chi tiết bước & Evidence'!$G$5:$G$63,"<>Pass") | J10: Danh sách lọc đúng theo từ khóa và trạng thái. | K10: =IF(H10=0,"Blocked",IF(I10=0,"Pass","Fail")) | L10: 09/10/2026 | M10: Nguyễn Thiện Hoàng
A11: 7 | B11: TC-EM07-01 | C11: EM-07 Chi tiết khóa học | D11: Xem chi tiết khóa học đang học | E11: Nhân viên xem tiến độ, danh sách bài và trạng thái bài đánh giá của khóa. | F11: Đã đăng nhập bằng employee@; khóa A4-I đang học. | G11: Khóa A4-I | H11: =COUNTIF('Chi tiết bước & Evidence'!$A$5:$A$63,B11) | I11: =COUNTIFS('Chi tiết bước & Evidence'!$A$5:$A$63,B11,'Chi tiết bước & Evidence'!$G$5:$G$63,"<>Pass") | J11: Thấy tiến độ, bài đã/chưa học, bài cuối khóa chưa mở. | K11: =IF(H11=0,"Blocked",IF(I11=0,"Pass","Fail")) | L11: 09/10/2026 | M11: Nguyễn Thiện Hoàng
A12: 8 | B12: TC-EM08-01 | C12: EM-08 Nội dung bài học | D12: Học bài tiếp theo và đánh dấu hoàn thành | E12: Nhân viên mở bài tiếp theo, đọc nội dung và ghi nhận hoàn thành. | F12: Đang ở trang chi tiết khóa A4-I. | G12: — | H12: =COUNTIF('Chi tiết bước & Evidence'!$A$5:$A$63,B12) | I12: =COUNTIFS('Chi tiết bước & Evidence'!$A$5:$A$63,B12,'Chi tiết bước & Evidence'!$G$5:$G$63,"<>Pass") | J12: Bài được ghi nhận hoàn thành và chuyển sang bài tiếp theo. | K12: =IF(H12=0,"Blocked",IF(I12=0,"Pass","Fail")) | L12: 09/10/2026 | M12: Nguyễn Thiện Hoàng
A13: 9 | B13: TC-EM09-01 | C13: EM-09 Danh sách bài đánh giá | D13: Xem và lọc danh sách bài đánh giá | E13: Nhân viên thấy bài nào làm được, bài nào đã đạt, bài nào chưa mở. | F13: Đã đăng nhập bằng employee@. | G13: Tab "Có thể làm" | H13: =COUNTIF('Chi tiết bước & Evidence'!$A$5:$A$63,B13) | I13: =COUNTIFS('Chi tiết bước & Evidence'!$A$5:$A$63,B13,'Chi tiết bước & Evidence'!$G$5:$G$63,"<>Pass") | J13: Tab lọc đúng; bài kiểm tra nhanh A4-I có thể làm. | K13: =IF(H13=0,"Blocked",IF(I13=0,"Pass","Fail")) | L13: 09/10/2026 | M13: Nguyễn Thiện Hoàng
A14: 10 | B14: TC-EM10-01 | C14: EM-10 Giới thiệu bài đánh giá | D14: Xem giới thiệu và quy chế bài kiểm tra | E14: Trước khi làm bài, nhân viên biết số câu, điểm đạt, số lượt và quy chế. | F14: Bài kiểm tra nhanh A4-I đang ở trạng thái Có thể làm. | G14: — | H14: =COUNTIF('Chi tiết bước & Evidence'!$A$5:$A$63,B14) | I14: =COUNTIFS('Chi tiết bước & Evidence'!$A$5:$A$63,B14,'Chi tiết bước & Evidence'!$G$5:$G$63,"<>Pass") | J14: Hiện thông tin bài và quy chế; nút Bắt đầu làm bài bật. | K14: =IF(H14=0,"Blocked",IF(I14=0,"Pass","Fail")) | L14: 09/10/2026 | M14: Nguyễn Thiện Hoàng
A15: 11 | B15: TC-EM11-01 | C15: EM-11 Làm bài đánh giá | D15: Làm bài: tự lưu, tải lại trang vẫn giữ đáp án, nộp bài | E15: Đáp án được lưu trên server; mất kết nối/tải lại vẫn làm tiếp đúng lượt; nộp bài có xác nhận. | F15: Đang ở trang giới thiệu bài kiểm tra nhanh A4-I. | G15: Đáp án đúng 4/4 câu | H15: =COUNTIF('Chi tiết bước & Evidence'!$A$5:$A$63,B15) | I15: =COUNTIFS('Chi tiết bước & Evidence'!$A$5:$A$63,B15,'Chi tiết bước & Evidence'!$G$5:$G$63,"<>Pass") | J15: Đáp án tự lưu, khôi phục sau khi tải lại, nộp thành công. | K15: =IF(H15=0,"Blocked",IF(I15=0,"Pass","Fail")) | L15: 09/10/2026 | M15: Nguyễn Thiện Hoàng
A16: 12 | B16: TC-EM12-01 | C16: EM-12 Kết quả đánh giá | D16: Xem kết quả và đáp án sau khi đạt | E16: Nhân viên thấy điểm, kết quả đạt/chưa đạt và đáp án (khi đã đạt). | F16: Vừa nộp bài kiểm tra nhanh A4-I với 4/4 câu đúng. | G16: — | H16: =COUNTIF('Chi tiết bước & Evidence'!$A$5:$A$63,B16) | I16: =COUNTIFS('Chi tiết bước & Evidence'!$A$5:$A$63,B16,'Chi tiết bước & Evidence'!$G$5:$G$63,"<>Pass") | J16: Đạt 100%, hiện đáp án đúng và giải thích. | K16: =IF(H16=0,"Blocked",IF(I16=0,"Pass","Fail")) | L16: 09/10/2026 | M16: Nguyễn Thiện Hoàng
... A24: 20 | B24: TC-SEC-02 | C24: Bảo mật | D24: Không xem được nhiệm vụ của người khác qua URL | E24: API /me chỉ trả dữ liệu của chính người đăng nhập — kể cả Quản lý. | F24: Đăng nhập bằng manager@ (không được giao nhiệm vụ này). | G24: /enterprise/me/tasks/e1a6c2e8-6c8b-462b-ae30-3cff21080eb1 | H24: =COUNTIF('Chi tiết bước & Evidence'!$A$5:$A$63,B24) | I24: =COUNTIFS('Chi tiết bước & Evidence'!$A$5:$A$63,B24,'Chi tiết bước & Evidence'!$G$5:$G$63,"<>Pass") | J24: Hiện 'Không tìm thấy nhiệm vụ'. | K24: =IF(H24=0,"Blocked",IF(I24=0,"Pass","Fail")) | L24: 09/10/2026 | M24: Nguyễn Thiện Hoàng

Sheet Test tự động
A1: TEST TỰ ĐỘNG CHO PHẦN EM-01 → EM-18
A2: Nguồn số liệu: báo cáo chạy thật trên nhánh feature/DT-em01-em18-tests — backend: dotnet test (xUnit, PostgreSQL 16 + EF InMemory); frontend: vitest (Testing Library).
A4: STT | B4: Tầng | C4: File test | D4: Màn hình | E4: Nội dung kiểm thử | F4: Số test | G4: Đạt | H4: Không đạt | I4: Commit | J4: Kết quả
A5: 1 | B5: Backend | C5: DigiTalent.Tests.Me.MyCompetencyOverviewTests | D5: EM-01 → 03 | E5: Dashboard, hồ sơ năng lực, khoảng trống trên dữ liệu demo thật; không có vị trí → lý do bỏ qua; không có hồ sơ → 403 | F5: 6 | G5: =F5-H5 | H5: 0 | I5: 3523e0b | J5: =IF(F5=0,"Blocked",IF(H5=0,"Pass","Fail"))
A6: 2 | B6: Backend | C6: DigiTalent.Tests.Me.MyGrowthJourneyTests | D6: EM-04, 05, 18 | E6: Dòng thời gian minh chứng chỉ của mình; lộ trình (khóa tiên quyết đứng trước); thành tựu và chứng chỉ | F6: 6 | G6: =F6-H6 | H6: 0 | I6: 4396b84 | J6: =IF(F6=0,"Blocked",IF(H6=0,"Pass","Fail"))
A7: 3 | B7: Backend | C7: DigiTalent.Tests.Me.MyCourseLearningTests | D7: EM-06 → 08 | E7: Khóa học của tôi, chi tiết khóa, mở/hoàn thành bài, tiến độ, mở khóa bài cuối khóa | F7: 5 | G7: =F7-H7 | H7: 0 | I7: 50bbf21 | J7: =IF(F7=0,"Blocked",IF(H7=0,"Pass","Fail"))
A8: 4 | B8: Backend | C8: DigiTalent.Tests.Me.MyAttemptSessionTests | D8: EM-10 → 13 | E8: Tự lưu đáp án, khôi phục khi tải lại, chặn lưu sau khi nộp, lịch sử lọc/phân trang | F8: 6 | G8: =F8-H8 | H8: 0 | I8: def57d6 | J8: =IF(F8=0,"Blocked",IF(H8=0,"Pass","Fail"))
A9: 5 | B9: Backend | C9: DigiTalent.Tests.Me.MyTaskEvidenceTests | D9: EM-14 → 17 | E9: Chi tiết nhiệm vụ, tải tệp vào thư mục nhiệm vụ, nộp + tải lại tệp, chặn nhiệm vụ/tệp của người khác | F9: 5 | G9: =F9-H9 | H9: 0 | I9: 9357b94 | J9: =IF(F9=0,"Blocked",IF(H9=0,"Pass","Fail"))
A10: 6 | B10: Backend | C10: DigiTalent.Tests.Me.MyTaskInputValidationTests | D10: EM-16 | E10: Kiểm tra dữ liệu: mô tả ≥ 20 ký tự, link http(s), tối đa 10 link/tệp, định dạng và dung lượng tệp | F10: 12 | G10: =F10-H10 | H10: 0 | I10: 9357b94 | J10: =IF(F10=0,"Blocked",IF(H10=0,"Pass","Fail"))
A11: 7 | B11: Backend | C11: DigiTalent.Tests.Me.MyAssessmentFlowTests | D11: EM-09 → 13 | E11: Khóa bài cuối khóa, chấm điểm, hết giờ, giới hạn lượt, cấp chứng chỉ (từ PR #53) | F11: 7 | G11: =F11-H11 | H11: 0 | I11: 0e80637 | J11: =IF(F11=0,"Blocked",IF(H11=0,"Pass","Fail"))
A12: 8 | B12: Backend | C12: DigiTalent.Tests.Me.MyTaskAndCourseTests | D12: EM-06 → 17 | E12: Nhiệm vụ của mình, nộp/nộp lại, tự ghi danh khóa tiên quyết (từ PR #53) | F12: 6 | G12: =F12-H12 | H12: 0 | I12: 0e80637 | J12: =IF(F12=0,"Blocked",IF(H12=0,"Pass","Fail"))
A13: 9 | B13: Backend | C13: DigiTalent.Tests.Me.MyHelpersTests | D13: EM-05, 16 | E13: Đọc rubric, liên kết minh chứng, sắp xếp lộ trình (từ PR #53) | F13: 7 | G13: =F13-H13 | H13: 0 | I13: 0e80637 | J13: =IF(F13=0,"Blocked",IF(H13=0,"Pass","Fail"))
A14: 10 | B14: Backend | C14: DigiTalent.Tests.Persistence.EmployeeJourneySeederTests | D14: Dữ liệu demo | E14: Seed dữ liệu demo EM đúng kịch bản, chạy lại không nhân đôi (từ PR #53) | F14: 2 | G14: =F14-H14 | H14: 0 | I14: 0e80637 | J14: =IF(F14=0,"Blocked",IF(H14=0,"Pass","Fail"))
A15: 11 | B15: Frontend | C15: src/features/employee/__tests__/MyDevelopmentScreens.test.tsx | D15: EM-01 → 05 | E15: Đang tải, lỗi + thử lại, lọc minh chứng, ghi danh từ lộ trình | F15: 9 | G15: =F15-H15 | H15: 0 | I15: bcfc168 | J15: =IF(F15=0,"Blocked",IF(H15=0,"Pass","Fail"))
A16: 12 | B16: Frontend | C16: src/features/learning/__tests__/EmployeeLearningScreens.test.tsx | D16: EM-06 → 08 | E16: Lọc/tìm khóa học, chi tiết khóa, bài PASS_CHECK, video YouTube, chuyển sang bài đánh giá | F16: 7 | G16: =F16-H16 | H16: 0 | I16: ca7ffb0 | J16: =IF(F16=0,"Blocked",IF(H16=0,"Pass","Fail"))
... A21: 17 | B21: Frontend | C21: src/services/mock/server/__tests__/me-api.test.ts | D21: EM-01 → 18 | E21: Mock server /me/* (chế độ VITE_USE_MOCK) | F21: 5 | G21: =F21-H21 | H21: 0 | I21: 672cc81 | J21: =IF(F21=0,"Blocked",IF(H21=0,"Pass","Fail"))
E22: Tổng | F22: =SUM(F5:F21) | G22: =SUM(G5:G21) | H22: =SUM(H5:H21)
A24: Lệnh chạy lại:
A25: Backend: cd backend → đặt DIGITALENT_TEST_POSTGRES_CONNECTION (DB tên kết thúc _test) → dotnet test --filter "FullyQualifiedName~DigiTalent.Tests.Me"
A26: Frontend: cd frontend → npx vitest run src/features/employee src/features/learning/__tests__/Employee* src/services/mock/server/__tests__/me-api.test.ts

Sheet Chi tiết bước & Evidence
A1: CHI TIẾT TỪNG BƯỚC VÀ ẢNH EVIDENCE — EM-01 → EM-18
A2: Trong ảnh: khung đỏ = phần tử được thao tác/kiểm tra ở bước đó; nhãn vàng góc phải = mã test case và nội dung bước. Bước "bấm" được chụp ngay trước khi bấm.
A4: Mã TC | B4: Bước | C4: Thao tác | D4: Dữ liệu nhập | E4: Kết quả mong đợi | F4: Kết quả thực tế | G4: Trạng thái | H4: URL sau bước | I4: Tên ảnh | J4: Ảnh evidence
A5: TC-EM01-01 | B5: 1 | C5: Mở trang đăng nhập | D5: /login | E5: Hiển thị form đăng nhập | F5: Form có ô Email, Mật khẩu và nút Đăng nhập | G5: Pass | H5: /login | I5: TC-EM01-01_B01.png
A6: TC-EM01-01 | B6: 2 | C6: Nhập email và mật khẩu | D6: employee@digitalent.ai / Admin@1234 | E6: Hai ô được điền đúng giá trị | F6: Email = employee@digitalent.ai | G6: Pass | H6: /login | I6: TC-EM01-01_B02.png
A7: TC-EM01-01 | B7: 3 | C7: Bấm 'Đăng nhập' | E7: Chuyển đến /enterprise/me, tiêu đề 'Bảng phát triển của tôi' | F7: Hiển thị tiêu đề 'Bảng phát triển của tôi' — URL /enterprise/me | G7: Pass | H7: /enterprise/me | I7: TC-EM01-01_B03.png
A8: TC-EM01-01 | B8: 4 | C8: Kiểm tra 4 chỉ số tổng quan | E8: Thấy: năng lực đạt chuẩn, mức đáp ứng chuẩn vị trí, nhiệm vụ cần làm, chứng nhận còn hiệu lực | F8: NĂNG LỰC ĐẠT CHUẨN 6 / 21 Mức hiện tại TB: Cơ bản · yêu cầu TB 1.9 MỨC ĐÁP ỨNG CHUẨN VỊ TRÍ 62.03% Xem khoảng trống (15) → NHIỆM VỤ CẦN LÀM 2 0 đang chờ chấm CHỨNG NHẬN CÒN HIỆU LỰC 1 Xem thành tựu → | G8: Pass | H8: /enterprise/me | I8: TC-EM01-01_B04.png
A9: TC-EM01-01 | B9: 5 | C9: Kiểm tra khối "Khóa đào tạo của tôi" | E9: Khóa A4-I đang học, có nút Tiếp tục học | F9: A4-I · An toàn thông tin trong công việc Tiến độ 25% · 1/4 bài · Tiếp theo: Mật khẩu mạnh và xác thực hai lớp Hạn hoàn thành: 18/10/2026 | G9: Pass | H9: /enterprise/me | I9: TC-EM01-01_B05.png
A10: TC-EM02-01 | B10: 1 | C10: Mở menu Năng lực của tôi → 'Hồ sơ năng lực' | E10: Mở trang hồ sơ năng lực | F10: Hiển thị tiêu đề 'Hồ sơ năng lực của tôi' — URL /enterprise/me/competency | G10: Pass | H10: /enterprise/me/competency | I10: TC-EM02-01_B01.png
A11: TC-EM02-01 | B11: 2 | C11: Kiểm tra danh sách năng lực | E11: Mỗi dòng có mã năng lực TT02, mức hiện tại, mức yêu cầu | F11: Có các dòng năng lực TT02-1.1 … với mức hiện tại/yêu cầu | G11: Pass | H11: /enterprise/me/competency | I11: TC-EM02-01_B02.png
A12: TC-EM03-01 | B12: 1 | C12: Mở menu 'Khoảng trống năng lực' | E12: Hiển thị tổng hợp khoảng trống | F12: Hiển thị tiêu đề Khoảng trống năng lực của tôi (Skill Gap) | G12: Pass | H12: /enterprise/me/skill-gap | I12: TC-EM03-01_B01.png
A13: TC-EM03-01 | B13: 2 | C13: Kiểm tra khóa học gợi ý cho năng lực còn thiếu | E13: Năng lực thiếu có khóa học gợi ý (mức cao hơn mức hiện tại) | F13: Gợi ý: A1-I Trung cấp Chiến lược tìm kiếm và quản lý thông tin 7 giờ 30 phút Chưa bắt đầu | G13: Pass | H13: /enterprise/me/skill-gap | I13: TC-EM03-01_B02.png
A14: TC-EM03-01 | B14: 3 | C14: Bấm vào khóa học được gợi ý | E14: Mở trang chi tiết khóa học tương ứng | F14: Mở /enterprise/me/courses/7f0c9e98-9c7d-4ae9-938c-e1916162b29b — Chiến lược tìm kiếm và quản lý thông tin | G14: Pass | H14: /enterprise/me/courses/7f0c9e98-9c7d-4ae9-938c-e1916162b29b | I14: TC-EM03-01_B03.png
A15: TC-EM04-01 | B15: 1 | C15: Mở menu 'Dòng thời gian minh chứng' | E15: Hiển thị toàn bộ minh chứng mới nhất trước | F15: Hiển thị tiêu đề 'Dòng thời gian minh chứng' — URL /enterprise/me/evidence | G15: Pass | H15: /enterprise/me/evidence | I15: TC-EM04-01_B01.png
A16: TC-EM04-01 | B16: 2 | C16: Bấm tab 'Cần chỉnh sửa' | D16: Tab Cần chỉnh sửa | E16: Chỉ còn bài "Chuẩn hóa quy trình lưu trữ hóa đơn điện tử" | F16: Chỉ hiện bài cần chỉnh sửa; bài đã duyệt bị ẩn | G16: Pass | H16: /enterprise/me/evidence | I16: TC-EM04-01_B02.png
A17: TC-EM05-01 | B17: 1 | C17: Mở menu Học tập → 'Lộ trình của tôi' | E17: Hiển thị các chặng: đã hoàn thành, đang học, được đề xuất | F17: Hiển thị tiêu đề 'Lộ trình học tập của tôi' — URL /enterprise/me/learning-path | G17: Pass | H17: /enterprise/me/learning-path | I17: TC-EM05-01_B01.png
A18: TC-EM05-01 | B18: 2 | C18: Xem lý do khóa học được đề xuất | E18: Mỗi khóa đề xuất có lý do (năng lực nào được bù) và điều kiện tiên quyết | F18: Gợi ý để bù khoảng trống năng lực: TT02-2.3 Sử dụng công nghệ số để thực hiện trách nhiệm công dân (Cơ bản → Trung cấp); TT02-2.2 Chia sẻ thông tin và nội dung thông qua công nghệ số (Cơ bản → Trung cấp); TT02-2.4 Hợp tá | G18: Pass | H18: /enterprise/me/learning-path | I18: TC-EM05-01_B02.png
A19: TC-EM05-01 | B19: 3 | C19: Bấm 'Ghi danh & bắt đầu học' | E19: Thông báo đã ghi danh, mở trang chi tiết khóa học | F19: Mở /enterprise/me/courses/baef226f-fa99-42a1-90f3-167ffd254ba8 — Giao tiếp và cộng tác chuyên nghiệp | G19: Pass | H19: /enterprise/me/courses/baef226f-fa99-42a1-90f3-167ffd254ba8 | I19: TC-EM05-01_B03.png
A20: TC-EM06-01 | B20: 1 | C20: Mở menu Học tập → 'Khóa học của tôi' | E20: Hiển thị các khóa đã ghi danh | F20: Hiển thị tiêu đề 'Khóa học của tôi' — URL /enterprise/me/courses | G20: Pass | H20: /enterprise/me/courses | I20: TC-EM06-01_B01.png
A21: TC-EM06-01 | B21: 2 | C21: Gõ "A1" vào ô tìm kiếm | D21: A1 | E21: Chỉ còn khóa A1-I "Chiến lược tìm kiếm và quản lý thông tin" | F21: Chỉ còn khóa A1-I | G21: Pass | H21: /enterprise/me/courses | I21: TC-EM06-01_B02.png
A22: TC-EM06-01 | B22: 3 | C22: Xóa từ khóa, bấm tab 'Đã xong' | D22: Tab Đã xong | E22: Chỉ còn khóa A2-F đã hoàn thành | F22: Hiện khóa A2-F đã hoàn thành | G22: Pass | H22: /enterprise/me/courses | I22: TC-EM06-01_B03.png
A23: TC-EM07-01 | B23: 1 | C23: Bấm tab 'Tất cả' | E23: Hiện lại toàn bộ khóa học, gồm khóa A4-I đang học | F23: Hiện khóa A4-I đang học 25% | G23: Pass | H23: /enterprise/me/courses | I23: TC-EM07-01_B01.png
A24: TC-EM07-01 | B24: 2 | C24: Bấm 'Học tiếp' trên thẻ khóa A4-I | D24: A4-I | E24: Mở trang chi tiết khóa A4-I | F24: Mở /enterprise/me/courses/03b96232-494a-452a-815b-92a1c2d02c52 | G24: Pass | H24: /enterprise/me/courses/03b96232-494a-452a-815b-92a1c2d02c52 | I24: TC-EM07-01_B02.png
A25: TC-EM07-01 | B25: 3 | C25: Kiểm tra tiến độ và danh sách bài học | E25: Thanh tiến độ và bài đã học / chưa học | F25: Tiến độ (1/4 bài) | G25: Pass | H25: /enterprise/me/courses/03b96232-494a-452a-815b-92a1c2d02c52 | I25: TC-EM07-01_B03.png
A26: TC-EM07-01 | B26: 4 | C26: Kiểm tra bài đánh giá cuối khóa | E26: Bài cuối khóa ở trạng thái "Chưa mở" cho tới khi học xong | F26: Bài đánh giá của khóa học Kiểm tra nhanh Có thể làm Kiểm tra nhanh: An toàn thông tin 4 câu · đạt từ 60% Cuối khóa Chưa mở Đánh giá cuối khóa A4-I: An toàn thông tin trong công việc 6 câu · đạt từ 70% · 15 phút | G26: Pass | H26: /enterprise/me/courses/03b96232-494a-452a-815b-92a1c2d02c52 | I26: TC-EM07-01_B04.png
A27: TC-EM08-01 | B27: 1 | C27: Bấm 'Tiếp tục bài học' | E27: Mở bài 'Mật khẩu mạnh và xác thực hai lớp' | F27: Hiển thị tiêu đề 'Mật khẩu mạnh và xác thực hai lớp' — URL /enterprise/me/courses/03b96232-494a-452a-815b-92a1c2d02c52/lessons/3d7b5575-f723-4c01-a9ed-59d12498d800 | G27: Pass | H27: /enterprise/me/courses/03b96232-494a-452a-815b-92a1c2d02c52/lessons/3d7b5575-f723-4c01-a9ed-59d12498d800 | I27: TC-EM08-01_B01.png
A28: TC-EM08-01 | B28: 2 | C28: Xem nội dung và vị trí bài trong khóa | E28: Hiện "Bài x/y · Khóa n%" và nội dung bài | F28: Bài 2/5 · Khóa 25% | G28: Pass | H28: /enterprise/me/courses/03b96232-494a-452a-815b-92a1c2d02c52/lessons/3d7b5575-f723-4c01-a9ed-59d12498d800 | I28: TC-EM08-01_B02.png
A29: TC-EM08-01 | B29: 3 | C29: Bấm 'Hoàn thành & sang bài tiếp theo' | E29: Thông báo 'Đã ghi nhận hoàn thành bài học!' và mở bài kế tiếp | F29: Đã chuyển sang bài: Nguyên tắc xử lý dữ liệu cá nhân | G29: Pass | H29: /enterprise/me/courses/03b96232-494a-452a-815b-92a1c2d02c52/lessons/f08ff6da-c687-4300-8b73-218b7280e34e | I29: TC-EM08-01_B03.png
A30: TC-EM08-01 | B30: 4 | C30: Bấm 'Thoát' để rời chế độ học tập trung | E30: Quay về giao diện có menu bên trái | F30: Quay về /enterprise/me | G30: Pass | H30: /enterprise/me | I30: TC-EM08-01_B04.png
A31: TC-EM09-01 | B31: 1 | C31: Mở menu 'Đánh giá' | E31: Hiển thị danh sách bài đánh giá và số lượng theo trạng thái | F31: Hiển thị tiêu đề 'Danh sách bài đánh giá năng lực' — URL /enterprise/me/assessments | G31: Pass | H31: /enterprise/me/assessments | I31: TC-EM09-01_B01.png
A32: TC-EM09-01 | B32: 2 | C32: Bấm tab 'Có thể làm' | E32: Hiện 'Kiểm tra nhanh: An toàn thông tin' | F32: Hiện bài kiểm tra nhanh A4-I | G32: Pass | H32: /enterprise/me/assessments | I32: TC-EM09-01_B02.png
A33: TC-EM10-01 | B33: 1 | C33: Bấm 'Vào làm bài' ở bài kiểm tra nhanh | E33: Mở trang giới thiệu bài | F33: Hiển thị tiêu đề 'Kiểm tra nhanh: An toàn thông tin' — URL /enterprise/me/assessments/6c5d4e7a-37b7-4117-b627-e2e2a660c289 | G33: Pass | H33: /enterprise/me/assessments/6c5d4e7a-37b7-4117-b627-e2e2a660c289 | I33: TC-EM10-01_B01.png
A34: TC-EM10-01 | B34: 2 | C34: Đọc quy chế làm bài | E34: Có quy chế: tự lưu, đếm ngược theo server, xem đáp án khi đạt/hết lượt | F34: Quy chế hiển thị; nút Bắt đầu làm bài đang bật | G34: Pass | H34: /enterprise/me/assessments/6c5d4e7a-37b7-4117-b627-e2e2a660c289 | I34: TC-EM10-01_B02.png
A35: TC-EM11-01 | B35: 1 | C35: Bấm 'Bắt đầu làm bài' | E35: Mở trang làm bài, câu 1/4 | F35: URL /enterprise/me/assessments/6c5d4e7a-37b7-4117-b627-e2e2a660c289/attempt?attempt=7cfec30a-d5dd-4de1-b6d3-02bd0806bf11 | G35: Pass | H35: /enterprise/me/assessments/6c5d4e7a-37b7-4117-b627-e2e2a660c289/attempt?attempt=7cfec30a-d5dd-4de1-b6d3-02bd0806bf11 | I35: TC-EM11-01_B01.png
A36: TC-EM11-01 | B36: 2 | C36: Chọn đáp án câu 1 và chờ tự lưu | D36: Bật xác thực hai lớp (2FA) | E36: Đáp án được chọn, hiện 'Đã lưu' | F36: Hiện trạng thái "Đã lưu" sau khi chọn | G36: Pass | H36: /enterprise/me/assessments/6c5d4e7a-37b7-4117-b627-e2e2a660c289/attempt?attempt=7cfec30a-d5dd-4de1-b6d3-02bd0806bf11 | I36: TC-EM11-01_B02.png
A37: TC-EM11-01 | B37: 3 | C37: Tải lại trang (F5) giữa chừng | E37: Đáp án câu 1 vẫn được chọn (khôi phục từ server) | F37: Sau khi tải lại, câu 1 vẫn chọn "Bật xác thực hai lớp (2FA)" | G37: Pass | H37: /enterprise/me/assessments/6c5d4e7a-37b7-4117-b627-e2e2a660c289/attempt?attempt=7cfec30a-d5dd-4de1-b6d3-02bd0806bf11 | I37: TC-EM11-01_B03.png
A38: TC-EM11-01 | B38: 4 | C38: Trả lời câu 2 → 4 | D38: Thông tin sức khỏe của nhân viên; Không bấm link và báo bộ phận IT; Kiểm tra cơ sở cho phép chia sẻ và mã hóa file | E38: Bảng câu hỏi báo "Đã làm: 4 / 4 câu" | F38: Đã làm: 4 / 4 câu | G38: Pass | H38: /enterprise/me/assessments/6c5d4e7a-37b7-4117-b627-e2e2a660c289/attempt?attempt=7cfec30a-d5dd-4de1-b6d3-02bd0806bf11 | I38: TC-EM11-01_B04.png
A39: TC-EM11-01 | B39: 5 | C39: Bấm 'Nộp bài' | E39: Hộp thoại xác nhận báo đã trả lời đủ 4/4 câu | F39: Bạn đã trả lời đầy đủ 4/4 câu hỏi. Sẵn sàng nộp bài! | G39: Pass | H39: /enterprise/me/assessments/6c5d4e7a-37b7-4117-b627-e2e2a660c289/attempt?attempt=7cfec30a-d5dd-4de1-b6d3-02bd0806bf11 | I39: TC-EM11-01_B05.png
A40: TC-EM11-01 | B40: 6 | C40: Bấm 'Xác nhận nộp bài' | E40: Bài được chấm và chuyển sang trang kết quả | F40: Chuyển đến /enterprise/me/assessments/6c5d4e7a-37b7-4117-b627-e2e2a660c289/result?attempt=7cfec30a-d5dd-4de1-b6d3-02bd0806bf11 | G40: Pass | H40: /enterprise/me/assessments/6c5d4e7a-37b7-4117-b627-e2e2a660c289/result?attempt=7cfec30a-d5dd-4de1-b6d3-02bd0806bf11 | I40: TC-EM11-01_B06.png
A41: TC-EM12-01 | B41: 1 | C41: Kiểm tra kết quả tổng | E41: Thông báo 'Chúc mừng bạn đã đạt bài đánh giá!' và điểm 100% | F41: Đạt — 100%, 4/4 câu đúng | G41: Pass | H41: /enterprise/me/assessments/6c5d4e7a-37b7-4117-b627-e2e2a660c289/result?attempt=7cfec30a-d5dd-4de1-b6d3-02bd0806bf11 | I41: TC-EM12-01_B01.png
...
